<?xml version="1.0" encoding="UTF-8"?>
<testng-results skipped="0" failed="4" ignored="0" total="7" passed="3">
  <reporter-output>
    <line>
      <![CDATA[Exception in ExtentManager function]]>
    </line>
    <line>
      <![CDATA[C:\Users\satheeshnair\AppianJ&J\ExecutionReports\AutomationTestReport.html]]>
    </line>
    <line>
      <![CDATA[Exception in ExtentManager function]]>
    </line>
    <line>
      <![CDATA[Exception in ExtentManager function]]>
    </line>
    <line>
      <![CDATA[Exception in ExtentManager function]]>
    </line>
    <line>
      <![CDATA[Exception in ExtentManager function]]>
    </line>
    <line>
      <![CDATA[Exception in ExtentManager function]]>
    </line>
  </reporter-output>
  <suite name="Default suite" duration-ms="55438" started-at="2019-02-12T11:59:50Z" finished-at="2019-02-12T12:00:46Z">
    <groups>
    </groups>
    <test name="Default test" duration-ms="55438" started-at="2019-02-12T11:59:50Z" finished-at="2019-02-12T12:00:46Z">
      <class name="jj.test.TC_AddNewPosition">
        <test-method status="PASS" signature="setup()[pri:0, instance:jj.test.TC_AddNewPosition@204f30ec]" name="setup" is-config="true" duration-ms="5957" started-at="2019-02-12T11:59:44Z" finished-at="2019-02-12T11:59:50Z">
          <reporter-output>
          </reporter-output>
        </test-method> <!-- setup -->
        <test-method status="PASS" signature="testcase()[pri:0, instance:jj.test.TC_AddNewPosition@204f30ec]" name="testcase" duration-ms="9555" started-at="2019-02-12T11:59:50Z" finished-at="2019-02-12T12:00:00Z">
          <reporter-output>
            <line>
              <![CDATA[Exception in ExtentManager function]]>
            </line>
            <line>
              <![CDATA[C:\Users\satheeshnair\AppianJ&J\ExecutionReports\AutomationTestReport.html]]>
            </line>
          </reporter-output>
        </test-method> <!-- testcase -->
        <test-method status="PASS" signature="header()[pri:1, instance:jj.test.TC_AddNewPosition@204f30ec]" name="header" duration-ms="7554" started-at="2019-02-12T12:00:00Z" finished-at="2019-02-12T12:00:07Z">
          <reporter-output>
            <line>
              <![CDATA[Exception in ExtentManager function]]>
            </line>
          </reporter-output>
        </test-method> <!-- header -->
        <test-method status="FAIL" signature="clickondemand()[pri:2, instance:jj.test.TC_AddNewPosition@204f30ec]" name="clickondemand" duration-ms="3134" started-at="2019-02-12T12:00:07Z" finished-at="2019-02-12T12:00:11Z">
          <exception class="java.lang.AssertionError">
            <message>
              <![CDATA[no such demand]]>
            </message>
            <full-stacktrace>
              <![CDATA[java.lang.AssertionError: no such demand
at org.testng.Assert.fail(Assert.java:96)
at jj.test.TC_AddNewPosition.clickondemand(TC_AddNewPosition.java:95)
at sun.reflect.NativeMethodAccessorImpl.invoke0(Native Method)
at sun.reflect.NativeMethodAccessorImpl.invoke(NativeMethodAccessorImpl.java:62)
at sun.reflect.DelegatingMethodAccessorImpl.invoke(DelegatingMethodAccessorImpl.java:43)
at java.lang.reflect.Method.invoke(Method.java:498)
at org.testng.internal.MethodInvocationHelper.invokeMethod(MethodInvocationHelper.java:124)
at org.testng.internal.Invoker.invokeMethod(Invoker.java:583)
at org.testng.internal.Invoker.invokeTestMethod(Invoker.java:719)
at org.testng.internal.Invoker.invokeTestMethods(Invoker.java:989)
at org.testng.internal.TestMethodWorker.invokeTestMethods(TestMethodWorker.java:125)
at org.testng.internal.TestMethodWorker.run(TestMethodWorker.java:109)
at org.testng.TestRunner.privateRun(TestRunner.java:648)
at org.testng.TestRunner.run(TestRunner.java:505)
at org.testng.SuiteRunner.runTest(SuiteRunner.java:455)
at org.testng.SuiteRunner.runSequentially(SuiteRunner.java:450)
at org.testng.SuiteRunner.privateRun(SuiteRunner.java:415)
at org.testng.SuiteRunner.run(SuiteRunner.java:364)
at org.testng.SuiteRunnerWorker.runSuite(SuiteRunnerWorker.java:52)
at org.testng.SuiteRunnerWorker.run(SuiteRunnerWorker.java:84)
at org.testng.TestNG.runSuitesSequentially(TestNG.java:1208)
at org.testng.TestNG.runSuitesLocally(TestNG.java:1137)
at org.testng.TestNG.runSuites(TestNG.java:1049)
at org.testng.TestNG.run(TestNG.java:1017)
at org.testng.remote.AbstractRemoteTestNG.run(AbstractRemoteTestNG.java:114)
at org.testng.remote.RemoteTestNG.initAndRun(RemoteTestNG.java:251)
at org.testng.remote.RemoteTestNG.main(RemoteTestNG.java:77)
]]>
            </full-stacktrace>
          </exception> <!-- java.lang.AssertionError -->
          <reporter-output>
            <line>
              <![CDATA[Exception in ExtentManager function]]>
            </line>
          </reporter-output>
        </test-method> <!-- clickondemand -->
        <test-method status="FAIL" signature="addnewposition()[pri:3, instance:jj.test.TC_AddNewPosition@204f30ec]" name="addnewposition" duration-ms="10204" started-at="2019-02-12T12:00:11Z" finished-at="2019-02-12T12:00:21Z">
          <exception class="java.lang.AssertionError">
            <message>
              <![CDATA[Failed to Click on Add position button]]>
            </message>
            <full-stacktrace>
              <![CDATA[java.lang.AssertionError: Failed to Click on Add position button
at org.testng.Assert.fail(Assert.java:96)
at jj.test.TC_AddNewPosition.addnewposition(TC_AddNewPosition.java:117)
at sun.reflect.NativeMethodAccessorImpl.invoke0(Native Method)
at sun.reflect.NativeMethodAccessorImpl.invoke(NativeMethodAccessorImpl.java:62)
at sun.reflect.DelegatingMethodAccessorImpl.invoke(DelegatingMethodAccessorImpl.java:43)
at java.lang.reflect.Method.invoke(Method.java:498)
at org.testng.internal.MethodInvocationHelper.invokeMethod(MethodInvocationHelper.java:124)
at org.testng.internal.Invoker.invokeMethod(Invoker.java:583)
at org.testng.internal.Invoker.invokeTestMethod(Invoker.java:719)
at org.testng.internal.Invoker.invokeTestMethods(Invoker.java:989)
at org.testng.internal.TestMethodWorker.invokeTestMethods(TestMethodWorker.java:125)
at org.testng.internal.TestMethodWorker.run(TestMethodWorker.java:109)
at org.testng.TestRunner.privateRun(TestRunner.java:648)
at org.testng.TestRunner.run(TestRunner.java:505)
at org.testng.SuiteRunner.runTest(SuiteRunner.java:455)
at org.testng.SuiteRunner.runSequentially(SuiteRunner.java:450)
at org.testng.SuiteRunner.privateRun(SuiteRunner.java:415)
at org.testng.SuiteRunner.run(SuiteRunner.java:364)
at org.testng.SuiteRunnerWorker.runSuite(SuiteRunnerWorker.java:52)
at org.testng.SuiteRunnerWorker.run(SuiteRunnerWorker.java:84)
at org.testng.TestNG.runSuitesSequentially(TestNG.java:1208)
at org.testng.TestNG.runSuitesLocally(TestNG.java:1137)
at org.testng.TestNG.runSuites(TestNG.java:1049)
at org.testng.TestNG.run(TestNG.java:1017)
at org.testng.remote.AbstractRemoteTestNG.run(AbstractRemoteTestNG.java:114)
at org.testng.remote.RemoteTestNG.initAndRun(RemoteTestNG.java:251)
at org.testng.remote.RemoteTestNG.main(RemoteTestNG.java:77)
]]>
            </full-stacktrace>
          </exception> <!-- java.lang.AssertionError -->
          <reporter-output>
            <line>
              <![CDATA[Exception in ExtentManager function]]>
            </line>
          </reporter-output>
        </test-method> <!-- addnewposition -->
        <test-method status="FAIL" signature="addposition()[pri:4, instance:jj.test.TC_AddNewPosition@204f30ec]" name="addposition" duration-ms="6335" started-at="2019-02-12T12:00:21Z" finished-at="2019-02-12T12:00:27Z">
          <exception class="java.lang.AssertionError">
            <message>
              <![CDATA[Not able to complete position details]]>
            </message>
            <full-stacktrace>
              <![CDATA[java.lang.AssertionError: Not able to complete position details
at org.testng.Assert.fail(Assert.java:96)
at jj.test.TC_AddNewPosition.addposition(TC_AddNewPosition.java:165)
at sun.reflect.NativeMethodAccessorImpl.invoke0(Native Method)
at sun.reflect.NativeMethodAccessorImpl.invoke(NativeMethodAccessorImpl.java:62)
at sun.reflect.DelegatingMethodAccessorImpl.invoke(DelegatingMethodAccessorImpl.java:43)
at java.lang.reflect.Method.invoke(Method.java:498)
at org.testng.internal.MethodInvocationHelper.invokeMethod(MethodInvocationHelper.java:124)
at org.testng.internal.Invoker.invokeMethod(Invoker.java:583)
at org.testng.internal.Invoker.invokeTestMethod(Invoker.java:719)
at org.testng.internal.Invoker.invokeTestMethods(Invoker.java:989)
at org.testng.internal.TestMethodWorker.invokeTestMethods(TestMethodWorker.java:125)
at org.testng.internal.TestMethodWorker.run(TestMethodWorker.java:109)
at org.testng.TestRunner.privateRun(TestRunner.java:648)
at org.testng.TestRunner.run(TestRunner.java:505)
at org.testng.SuiteRunner.runTest(SuiteRunner.java:455)
at org.testng.SuiteRunner.runSequentially(SuiteRunner.java:450)
at org.testng.SuiteRunner.privateRun(SuiteRunner.java:415)
at org.testng.SuiteRunner.run(SuiteRunner.java:364)
at org.testng.SuiteRunnerWorker.runSuite(SuiteRunnerWorker.java:52)
at org.testng.SuiteRunnerWorker.run(SuiteRunnerWorker.java:84)
at org.testng.TestNG.runSuitesSequentially(TestNG.java:1208)
at org.testng.TestNG.runSuitesLocally(TestNG.java:1137)
at org.testng.TestNG.runSuites(TestNG.java:1049)
at org.testng.TestNG.run(TestNG.java:1017)
at org.testng.remote.AbstractRemoteTestNG.run(AbstractRemoteTestNG.java:114)
at org.testng.remote.RemoteTestNG.initAndRun(RemoteTestNG.java:251)
at org.testng.remote.RemoteTestNG.main(RemoteTestNG.java:77)
]]>
            </full-stacktrace>
          </exception> <!-- java.lang.AssertionError -->
          <reporter-output>
            <line>
              <![CDATA[Exception in ExtentManager function]]>
            </line>
          </reporter-output>
        </test-method> <!-- addposition -->
        <test-method status="FAIL" signature="submitposition()[pri:5, instance:jj.test.TC_AddNewPosition@204f30ec]" name="submitposition" duration-ms="7038" started-at="2019-02-12T12:00:27Z" finished-at="2019-02-12T12:00:34Z">
          <exception class="java.lang.AssertionError">
            <message>
              <![CDATA[Submit button missing]]>
            </message>
            <full-stacktrace>
              <![CDATA[java.lang.AssertionError: Submit button missing
at org.testng.Assert.fail(Assert.java:96)
at jj.test.TC_AddNewPosition.submitposition(TC_AddNewPosition.java:198)
at sun.reflect.NativeMethodAccessorImpl.invoke0(Native Method)
at sun.reflect.NativeMethodAccessorImpl.invoke(NativeMethodAccessorImpl.java:62)
at sun.reflect.DelegatingMethodAccessorImpl.invoke(DelegatingMethodAccessorImpl.java:43)
at java.lang.reflect.Method.invoke(Method.java:498)
at org.testng.internal.MethodInvocationHelper.invokeMethod(MethodInvocationHelper.java:124)
at org.testng.internal.Invoker.invokeMethod(Invoker.java:583)
at org.testng.internal.Invoker.invokeTestMethod(Invoker.java:719)
at org.testng.internal.Invoker.invokeTestMethods(Invoker.java:989)
at org.testng.internal.TestMethodWorker.invokeTestMethods(TestMethodWorker.java:125)
at org.testng.internal.TestMethodWorker.run(TestMethodWorker.java:109)
at org.testng.TestRunner.privateRun(TestRunner.java:648)
at org.testng.TestRunner.run(TestRunner.java:505)
at org.testng.SuiteRunner.runTest(SuiteRunner.java:455)
at org.testng.SuiteRunner.runSequentially(SuiteRunner.java:450)
at org.testng.SuiteRunner.privateRun(SuiteRunner.java:415)
at org.testng.SuiteRunner.run(SuiteRunner.java:364)
at org.testng.SuiteRunnerWorker.runSuite(SuiteRunnerWorker.java:52)
at org.testng.SuiteRunnerWorker.run(SuiteRunnerWorker.java:84)
at org.testng.TestNG.runSuitesSequentially(TestNG.java:1208)
at org.testng.TestNG.runSuitesLocally(TestNG.java:1137)
at org.testng.TestNG.runSuites(TestNG.java:1049)
at org.testng.TestNG.run(TestNG.java:1017)
at org.testng.remote.AbstractRemoteTestNG.run(AbstractRemoteTestNG.java:114)
at org.testng.remote.RemoteTestNG.initAndRun(RemoteTestNG.java:251)
at org.testng.remote.RemoteTestNG.main(RemoteTestNG.java:77)
]]>
            </full-stacktrace>
          </exception> <!-- java.lang.AssertionError -->
          <reporter-output>
            <line>
              <![CDATA[Exception in ExtentManager function]]>
            </line>
          </reporter-output>
        </test-method> <!-- submitposition -->
        <test-method status="PASS" signature="logout()[pri:6, instance:jj.test.TC_AddNewPosition@204f30ec]" name="logout" duration-ms="11586" started-at="2019-02-12T12:00:34Z" finished-at="2019-02-12T12:00:46Z">
          <reporter-output>
          </reporter-output>
        </test-method> <!-- logout -->
        <test-method status="PASS" signature="tearDown()[pri:0, instance:jj.test.TC_AddNewPosition@204f30ec]" name="tearDown" is-config="true" duration-ms="317" started-at="2019-02-12T12:00:46Z" finished-at="2019-02-12T12:00:46Z">
          <reporter-output>
          </reporter-output>
        </test-method> <!-- tearDown -->
      </class> <!-- jj.test.TC_AddNewPosition -->
    </test> <!-- Default test -->
  </suite> <!-- Default suite -->
</testng-results>
